Workbook

Sheet Screen Status
A1: Screen # | B1: Module | C1: Screen Name | D1: Type | E1: Priority | F1: Dev Hrs Est | G1: Development Status | H1: Development Done By | I1: DevTest Hrs Est | J1: Dev Testing Status | K1: Dev Tested By | L1: QA Hrs Est | M1: QA Testing Status | N1: QA Tested By
A2: 1 | B2: Fundraising | C2: Donation (Global) | D2: FLOW | E2: Medium | F2: 1 | G2: Completed | H2: Karthick | I2: 1.5 | J2: Passed | K2: Karthick | L2: 1.5 | M2: Not Started
A3: 2 | B3: Fundraising | C3: Donation Purpose | D3: MASTER_GRID | E3: Medium | F3: 0.5 | G3: Completed | H3: Karthick | I3: 0.75 | J3: Passed | K3: Saranya | L3: 0.75 | M3: Not Started
A4: 3 | B4: Fundraising | C4: Donation Category | D4: MASTER_GRID | E4: Medium | F4: 0.5 | G4: Completed | H4: Karthick | I4: 0.75 | J4: Passed | K4: Saranya | L4: 0.75 | M4: Not Started
A5: 4 | B5: Fundraising | C5: Donation Group | D5: MASTER_GRID | E5: Medium | F5: 0.5 | G5: Completed | H5: Karthick | I5: 0.75 | J5: Passed | K5: Saranya | L5: 0.75 | M5: Not Started
A6: 5 | B6: Fundraising | C6: Bulk Donation | D6: FLOW | E6: Medium | F6: 0.75 | G6: Completed | H6: Karthick | I6: 1 | J6: Not Started | L6: 1 | M6: Not Started
A7: 6 | B7: Fundraising | C7: Cheque Donation | D7: FLOW | E7: Medium | F7: 1 | G7: Completed | H7: Karthick | I7: 1.5 | J7: Passed | K7: Karthick | L7: 1.5 | M7: Not Started
A8: 7 | B8: Fundraising | C8: In-Kind Donation | D8: FLOW | E8: Medium | F8: 1 | G8: Completed | H8: Karthick | I8: 1.5 | J8: Passed | K8: Saranya | L8: 1.5 | M8: Not Started
A9: 8 | B9: Fundraising | C9: Recurring Donation | D9: FLOW | E9: Medium | F9: 1 | G9: Completed | H9: Karthick | I9: 1.5 | J9: Passed | K9: Karthick | L9: 1.5 | M9: Not Started
A10: 9 | B10: Fundraising | C10: Receipt (GlobalReceipt) | D10: FLOW | E10: Medium | F10: 0.75 | G10: Completed | H10: Karthick | I10: 1 | J10: Not Started | L10: 1 | M10: Not Started
A11: 10 | B11: Fundraising | C11: Online Donation Setup | D11: FLOW | E11: Medium | F11: 1 | G11: Completed | H11: Karthick | I11: 1.5 | J11: Passed | K11: Karthick | L11: 1.5 | M11: Not Started
A12: 11 | B12: Fundraising | C12: Matching Gift | D12: FLOW | E12: High | F12: 1 | G12: Completed | H12: Karthick | I12: 1.5 | J12: Pending | K12: Karthick | L12: 1.5 | M12: Not Started
A13: 12 | B13: Fundraising | C13: Pledge | D13: FLOW | E13: High | F13: 1 | G13: Completed | H13: Karthick | I13: 1.5 | J13: Pending | K13: Kavin | L13: 1.5 | M13: Not Started
A14: 13 | B14: Fundraising | C14: Refund | D14: FLOW | E14: Medium | F14: 1 | G14: Completed | H14: Karthick | I14: 1.5 | J14: Pending | K14: Karthick | L14: 1.5 | M14: Not Started
A15: 14 | B15: Fundraising | C15: Payment Reconciliation | D15: FLOW | E15: Medium | F15: 1 | G15: Completed | H15: Karthick | I15: 1.5 | J15: Passed | K15: Karthick | L15: 1.5 | M15: Not Started
A16: 15 | B16: Fundraising | C16: P2P Campaign | D16: FLOW | E16: Medium | F16: 1 | G16: Completed | H16: Karthick | I16: 1.5 | J16: In Testing | K16: Karthick | L16: 1.5 | M16: Not Started
A17: 16 | B17: Fundraising | C17: Crowdfunding | D17: FLOW | E17: Medium | F17: 1 | G17: Completed | H17: Karthick | I17: 1.5 | J17: Passed | K17: Karthick | L17: 1.5 | M17: Not Started
A18: 18 | B18: Contacts | C18: Contact | D18: FLOW | E18: Medium | F18: 1 | G18: Completed | H18: Karthick | I18: 1.5 | J18: Passed | K18: Kavin | L18: 1.5 | M18: Not Started
A19: 19 | B19: Contacts | C19: Contact Type | D19: MASTER_GRID | E19: Medium | F19: 0.5 | G19: Completed | H19: Karthick | I19: 0.75 | J19: Passed | K19: Saranya | L19: 0.75 | M19: Not Started
A20: 20 | B20: Contacts | C20: Family | D20: FLOW | E20: Medium | F20: 1 | G20: Completed | H20: Karthick | I20: 1.5 | J20: Passed | K20: Saranya | L20: 1.5 | M20: Not Started
A21: 21 | B21: Contacts | C21: Duplicate Detection | D21: FLOW | E21: Medium | F21: 1 | G21: Completed | H21: Karthick | I21: 1.5 | J21: Pending | K21: Karthick | L21: 1.5 | M21: Not Started
A22: 22 | B22: Contacts | C22: Tags & Segmentation | D22: MASTER_GRID | E22: High | F22: 0.75 | G22: Completed | H22: Karthick | I22: 1 | J22: Passed | K22: Saranya | L22: 1 | M22: Not Started
... A24: 24 | B24: Communication | C24: Email Template | D24: FLOW | E24: Medium | F24: 0.75 | G24: Completed | H24: Karthick | I24: 1 | J24: Passed | K24: Saranya | L24: 1 | M24: Not Started
A25: 25 | B25: Communication | C25: Email Campaign/SendJob | D25: FLOW | E25: Medium | F25: 1 | G25: Completed | H25: Saranya | I25: 1.5 | J25: Not Started | L25: 1.5 | M25: Not Started
A26: 26 | B26: Communication | C26: Placeholder Definition | D26: MASTER_GRID | E26: Medium | F26: 0.5 | G26: Completed | H26: Karthick | I26: 0.75 | J26: Passed | K26: Saranya | L26: 0.75 | M26: Not Started
A27: 27 | B27: Communication | C27: Saved Filter | D27: FLOW | E27: Medium | F27: 0.75 | G27: Completed | H27: Karthick | I27: 1 | J27: Passed | K27: Saranya | L27: 1 | M27: Not Started
A28: 28 | B28: Communication | C28: Company Email Provider | D28: FLOW | E28: Medium | F28: 0.75 | G28: Completed | H28: Karthick | I28: 1 | J28: In Testing | K28: Karthick | L28: 1 | M28: Not Started
A29: 29 | B29: Communication | C29: SMS Template | D29: FLOW | E29: High | F29: 0.75 | G29: Completed | H29: Karthick | I29: 1 | J29: Passed | K29: Saranya | L29: 1 | M29: Not Started
A30: 30 | B30: Communication | C30: SMS Campaign | D30: FLOW | E30: Medium | F30: 1 | G30: Completed | H30: Karthick | I30: 1.5 | J30: Working | K30: Saranya | L30: 1.5 | M30: Not Started
A31: 31 | B31: Communication | C31: WhatsApp Template | D31: FLOW | E31: High | F31: 0.75 | G31: Completed | H31: Karthick | I31: 1 | J31: Pending | K31: Karthick | L31: 1 | M31: Not Started
A32: 32 | B32: Communication | C32: WhatsApp Campaign | D32: FLOW | E32: Medium | F32: 1 | G32: Completed | H32: Kavin | I32: 1.5 | J32: Not Started | K32: Kavin | L32: 1.5 | M32: Not Started
A33: 33 | B33: Communication | C33: WhatsApp Conversations | D33: FLOW | E33: Medium | F33: 1 | G33: Completed | H33: Karthick | I33: 1.5 | J33: Not Started | K33: Kavin | L33: 1.5 | M33: Not Started
A34: 34 | B34: Communication | C34: WhatsApp Setup | D34: Config | E34: High | F34: 0.75 | G34: Completed | H34: Kavin | I34: 1 | J34: Not Started | K34: Kavin | L34: 1 | M34: Not Started
A35: 35 | B35: Communication | C35: Notification Center | D35: FLOW | E35: Medium | F35: 0.75 | G35: Completed | H35: Karthick | I35: 1 | J35: Passed | K35: Kavin | L35: 1 | M35: Not Started
A36: 36 | B36: Communication | C36: Notification Templates | D36: FLOW | E36: High | F36: 0.75 | G36: Completed | H36: Karthick | I36: 1 | J36: Passed | K36: Kavin | L36: 1 | M36: Not Started
A37: 37 | B37: Communication | C37: Automation Workflow | D37: FLOW | E37: Low | F37: 1 | G37: Completed | H37: Karthick | I37: 1.5 | J37: Not Started | L37: 1.5 | M37: Not Started
A38: 38 | B38: Communication | C38: Email Analytics | D38: Dashboard | E38: Low | F38: 0.75 | G38: Completed | H38: Karthick | I38: 1 | J38: Passed | K38: Karthick | L38: 1 | M38: N/A (Upcoming)
A39: 39 | B39: Organization | C39: Campaign | D39: FLOW | E39: Medium | F39: 0.75 | G39: Completed | H39: Karthick | I39: 1 | J39: Passed | K39: Kavin | L39: 1 | M39: Not Started
A40: 40 | B40: Organization | C40: Event | D40: FLOW | E40: Medium | F40: 1 | G40: Completed | H40: Karthick | I40: 1.5 | J40: Passed | K40: Karthick | L40: 1.5 | M40: Not Started
A41: 41 | B41: Organization | C41: Branch | D41: MASTER_GRID | E41: Medium | F41: 0.5 | G41: Completed | H41: Karthick | I41: 0.75 | J41: Passed | K41: Kavin | L41: 0.75 | M41: Not Started
...

Sheet Lookups
A1: Development Status | B1: Testing Status | C1: Team Members | D1: Priority
A2: Completed | B2: Not Started | C2: Karthick | D2: High
A3: Completed - Needs Fix | B3: Pending | C3: Saranya | D3: Medium
A4: Ready to Build | B4: In Testing | C4: Kavin | D4: Low
A5: In Progress (Partial) | B5: Passed | C5: Sangeetha
A6: Not Started | B6: Failed | C6: Shyam
A7: Upcoming (Dashboard) | B7: Issues Found | C7: Ganesh
A8: Upcoming (Config) | B8: Blocked - Awaiting Fix
A9: Upcoming (Mobile) | B9: N/A (Upcoming)
A10: Upcoming

Sheet Summary
A1: PSS 2.0 — Screen Status Summary
A2: Generated 2026-04-28 · Total screens: 138 · Source: Screen Status sheet (live formulas)
A4: Total | B4: Completed | C4: Needs Fix | D4: In Progress | E4: Ready to Build | F4: Not Started | G4: Upcoming | H4: Dev Tested (Passed) | I4: QA Tested (Passed)
A5: =COUNTA('Screen Status'!A2:A144) -> 140 | B5: =COUNTIF('Screen Status'!G2:G144,"Completed") -> 131 | C5: =COUNTIF('Screen Status'!G2:G144,"Completed - Needs Fix") -> 0 | D5: =COUNTIF('Screen Status'!G2:G144,"In Progress (Partial)") -> 1 | E5: =COUNTIF('Screen Status'!G2:G144,"Ready to Build") -> 0 | F5: =COUNTIF('Screen Status'!G2:G144,"Not Started") -> 1 | G5: =COUNTIF('Screen Status'!G2:G144,"Upcoming*") -> 7 | H5: =COUNTIF('Screen Status'!J2:J144,"Passed") -> 61 | I5: =COUNTIF('Screen Status'!L2:L144,"Passed") -> 0
A7: ① Development Status by Module
A8: Module | B8: Completed | C8: Completed - Needs Fix | D8: Ready to Build | E8: In Progress (Partial) | F8: Not Started | G8: Upcoming (Dashboard) | H8: Upcoming (Config) | I8: Upcoming (Mobile) | J8: Upcoming | K8: Total
A9: AI Intelligence | B9: =COUNTIFS('Screen Status'!B2:B144,"AI Intelligence",'Screen Status'!G2:G144,"Completed") -> 0 | C9: =COUNTIFS('Screen Status'!B2:B144,"AI Intelligence",'Screen Status'!G2:G144,"Completed - Needs Fix") -> 0 | D9: =COUNTIFS('Screen Status'!B2:B144,"AI Intelligence",'Screen Status'!G2:G144,"Ready to Build") -> 0 | E9: =COUNTIFS('Screen Status'!B2:B144,"AI Intelligence",'Screen Status'!G2:G144,"In Progress (Partial)") -> 0 | F9: =COUNTIFS('Screen Status'!B2:B144,"AI Intelligence",'Screen Status'!G2:G144,"Not Started") -> 0 | G9: =COUNTIFS('Screen Status'!B2:B144,"AI Intelligence",'Screen Status'!G2:G144,"Upcoming (Dashboard)") -> 0 | H9: =COUNTIFS('Screen Status'!B2:B144,"AI Intelligence",'Screen Status'!G2:G144,"Upcoming (Config)") -> 0 | I9: =COUNTIFS('Screen Status'!B2:B144,"AI Intelligence",'Screen Status'!G2:G144,"Upcoming (Mobile)") -> 0 | J9: =COUNTIFS('Screen Status'!B2:B144,"AI Intelligence",'Screen Status'!G2:G144,"Upcoming") -> 6 | K9: =COUNTIF('Screen Status'!B2:B144,"AI Intelligence") -> 6
A10: Administration | B10: =COUNTIFS('Screen Status'!B2:B144,"Administration",'Screen Status'!G2:G144,"Completed") -> 6 | C10: =COUNTIFS('Screen Status'!B2:B144,"Administration",'Screen Status'!G2:G144,"Completed - Needs Fix") -> 0 | D10: =COUNTIFS('Screen Status'!B2:B144,"Administration",'Screen Status'!G2:G144,"Ready to Build") -> 0 | E10: =COUNTIFS('Screen Status'!B2:B144,"Administration",'Screen Status'!G2:G144,"In Progress (Partial)") -> 0 | F10: =COUNTIFS('Screen Status'!B2:B144,"Administration",'Screen Status'!G2:G144,"Not Started") -> 0 | G10: =COUNTIFS('Screen Status'!B2:B144,"Administration",'Screen Status'!G2:G144,"Upcoming (Dashboard)") -> 0 | H10: =COUNTIFS('Screen Status'!B2:B144,"Administration",'Screen Status'!G2:G144,"Upcoming (Config)") -> 0 | I10: =COUNTIFS('Screen Status'!B2:B144,"Administration",'Screen Status'!G2:G144,"Upcoming (Mobile)") -> 0 | J10: =COUNTIFS('Screen Status'!B2:B144,"Administration",'Screen Status'!G2:G144,"Upcoming") -> 0 | K10: =COUNTIF('Screen Status'!B2:B144,"Administration") -> 6
A11: Case Management | B11: =COUNTIFS('Screen Status'!B2:B144,"Case Management",'Screen Status'!G2:G144,"Completed") -> 4 | C11: =COUNTIFS('Screen Status'!B2:B144,"Case Management",'Screen Status'!G2:G144,"Completed - Needs Fix") -> 0 | D11: =COUNTIFS('Screen Status'!B2:B144,"Case Management",'Screen Status'!G2:G144,"Ready to Build") -> 0 | E11: =COUNTIFS('Screen Status'!B2:B144,"Case Management",'Screen Status'!G2:G144,"In Progress (Partial)") -> 0 | F11: =COUNTIFS('Screen Status'!B2:B144,"Case Management",'Screen Status'!G2:G144,"Not Started") -> 0 | G11: =COUNTIFS('Screen Status'!B2:B144,"Case Management",'Screen Status'!G2:G144,"Upcoming (Dashboard)") -> 0 | H11: =COUNTIFS('Screen Status'!B2:B144,"Case Management",'Screen Status'!G2:G144,"Upcoming (Config)") -> 0 | I11: =COUNTIFS('Screen Status'!B2:B144,"Case Management",'Screen Status'!G2:G144,"Upcoming (Mobile)") -> 0 | J11: =COUNTIFS('Screen Status'!B2:B144,"Case Management",'Screen Status'!G2:G144,"Upcoming") -> 0 | K11: =COUNTIF('Screen Status'!B2:B144,"Case Management") -> 4
A12: Communication | B12: =COUNTIFS('Screen Status'!B2:B144,"Communication",'Screen Status'!G2:G144,"Completed") -> 17 | C12: =COUNTIFS('Screen Status'!B2:B144,"Communication",'Screen Status'!G2:G144,"Completed - Needs Fix") -> 0 | D12: =COUNTIFS('Screen Status'!B2:B144,"Communication",'Screen Status'!G2:G144,"Ready to Build") -> 0 | E12: =COUNTIFS('Screen Status'!B2:B144,"Communication",'Screen Status'!G2:G144,"In Progress (Partial)") -> 0 | F12: =COUNTIFS('Screen Status'!B2:B144,"Communication",'Screen Status'!G2:G144,"Not Started") -> 0 | G12: =COUNTIFS('Screen Status'!B2:B144,"Communication",'Screen Status'!G2:G144,"Upcoming (Dashboard)") -> 0 | H12: =COUNTIFS('Screen Status'!B2:B144,"Communication",'Screen Status'!G2:G144,"Upcoming (Config)") -> 0 | I12: =COUNTIFS('Screen Status'!B2:B144,"Communication",'Screen Status'!G2:G144,"Upcoming (Mobile)") -> 0 | J12: =COUNTIFS('Screen Status'!B2:B144,"Communication",'Screen Status'!G2:G144,"Upcoming") -> 0 | K12: =COUNTIF('Screen Status'!B2:B144,"Communication") -> 17
A13: Contacts | B13: =COUNTIFS('Screen Status'!B2:B144,"Contacts",'Screen Status'!G2:G144,"Completed") -> 8 | C13: =COUNTIFS('Screen Status'!B2:B144,"Contacts",'Screen Status'!G2:G144,"Completed - Needs Fix") -> 0 | D13: =COUNTIFS('Screen Status'!B2:B144,"Contacts",'Screen Status'!G2:G144,"Ready to Build") -> 0 | E13: =COUNTIFS('Screen Status'!B2:B144,"Contacts",'Screen Status'!G2:G144,"In Progress (Partial)") -> 0 | F13: =COUNTIFS('Screen Status'!B2:B144,"Contacts",'Screen Status'!G2:G144,"Not Started") -> 0 | G13: =COUNTIFS('Screen Status'!B2:B144,"Contacts",'Screen Status'!G2:G144,"Upcoming (Dashboard)") -> 0 | H13: =COUNTIFS('Screen Status'!B2:B144,"Contacts",'Screen Status'!G2:G144,"Upcoming (Config)") -> 0 | I13: =COUNTIFS('Screen Status'!B2:B144,"Contacts",'Screen Status'!G2:G144,"Upcoming (Mobile)") -> 0 | J13: =COUNTIFS('Screen Status'!B2:B144,"Contacts",'Screen Status'!G2:G144,"Upcoming") -> 0 | K13: =COUNTIF('Screen Status'!B2:B144,"Contacts") -> 8
A14: Field Collection | B14: =COUNTIFS('Screen Status'!B2:B144,"Field Collection",'Screen Status'!G2:G144,"Completed") -> 6 | C14: =COUNTIFS('Screen Status'!B2:B144,"Field Collection",'Screen Status'!G2:G144,"Completed - Needs Fix") -> 0 | D14: =COUNTIFS('Screen Status'!B2:B144,"Field Collection",'Screen Status'!G2:G144,"Ready to Build") -> 0 | E14: =COUNTIFS('Screen Status'!B2:B144,"Field Collection",'Screen Status'!G2:G144,"In Progress (Partial)") -> 0 | F14: =COUNTIFS('Screen Status'!B2:B144,"Field Collection",'Screen Status'!G2:G144,"Not Started") -> 0 | G14: =COUNTIFS('Screen Status'!B2:B144,"Field Collection",'Screen Status'!G2:G144,"Upcoming (Dashboard)") -> 0 | H14: =COUNTIFS('Screen Status'!B2:B144,"Field Collection",'Screen Status'!G2:G144,"Upcoming (Config)") -> 0 | I14: =COUNTIFS('Screen Status'!B2:B144,"Field Collection",'Screen Status'!G2:G144,"Upcoming (Mobile)") -> 0 | J14: =COUNTIFS('Screen Status'!B2:B144,"Field Collection",'Screen Status'!G2:G144,"Upcoming") -> 0 | K14: =COUNTIF('Screen Status'!B2:B144,"Field Collection") -> 6
A15: Fundraising | B15: =COUNTIFS('Screen Status'!B2:B144,"Fundraising",'Screen Status'!G2:G144,"Completed") -> 18 | C15: =COUNTIFS('Screen Status'!B2:B144,"Fundraising",'Screen Status'!G2:G144,"Completed - Needs Fix") -> 0 | D15: =COUNTIFS('Screen Status'!B2:B144,"Fundraising",'Screen Status'!G2:G144,"Ready to Build") -> 0 | E15: =COUNTIFS('Screen Status'!B2:B144,"Fundraising",'Screen Status'!G2:G144,"In Progress (Partial)") -> 0 | F15: =COUNTIFS('Screen Status'!B2:B144,"Fundraising",'Screen Status'!G2:G144,"Not Started") -> 0 | G15: =COUNTIFS('Screen Status'!B2:B144,"Fundraising",'Screen Status'!G2:G144,"Upcoming (Dashboard)") -> 0 | H15: =COUNTIFS('Screen Status'!B2:B144,"Fundraising",'Screen Status'!G2:G144,"Upcoming (Config)") -> 0 | I15: =COUNTIFS('Screen Status'!B2:B144,"Fundraising",'Screen Status'!G2:G144,"Upcoming (Mobile)") -> 0 | J15: =COUNTIFS('Screen Status'!B2:B144,"Fundraising",'Screen Status'!G2:G144,"Upcoming") -> 0 | K15: =COUNTIF('Screen Status'!B2:B144,"Fundraising") -> 18
A16: Grants | B16: =COUNTIFS('Screen Status'!B2:B144,"Grants",'Screen Status'!G2:G144,"Completed") -> 3 | C16: =COUNTIFS('Screen Status'!B2:B144,"Grants",'Screen Status'!G2:G144,"Completed - Needs Fix") -> 0 | D16: =COUNTIFS('Screen Status'!B2:B144,"Grants",'Screen Status'!G2:G144,"Ready to Build") -> 0 | E16: =COUNTIFS('Screen Status'!B2:B144,"Grants",'Screen Status'!G2:G144,"In Progress (Partial)") -> 0 | F16: =COUNTIFS('Screen Status'!B2:B144,"Grants",'Screen Status'!G2:G144,"Not Started") -> 0 | G16: =COUNTIFS('Screen Status'!B2:B144,"Grants",'Screen Status'!G2:G144,"Upcoming (Dashboard)") -> 0 | H16: =COUNTIFS('Screen Status'!B2:B144,"Grants",'Screen Status'!G2:G144,"Upcoming (Config)") -> 0 | I16: =COUNTIFS('Screen Status'!B2:B144,"Grants",'Screen Status'!G2:G144,"Upcoming (Mobile)") -> 0 | J16: =COUNTIFS('Screen Status'!B2:B144,"Grants",'Screen Status'!G2:G144,"Upcoming") -> 0 | K16: =COUNTIF('Screen Status'!B2:B144,"Grants") -> 3
A17: Membership | B17: =COUNTIFS('Screen Status'!B2:B144,"Membership",'Screen Status'!G2:G144,"Completed") -> 4 | C17: =COUNTIFS('Screen Status'!B2:B144,"Membership",'Screen Status'!G2:G144,"Completed - Needs Fix") -> 0 | D17: =COUNTIFS('Screen Status'!B2:B144,"Membership",'Screen Status'!G2:G144,"Ready to Build") -> 0 | E17: =COUNTIFS('Screen Status'!B2:B144,"Membership",'Screen Status'!G2:G144,"In Progress (Partial)") -> 0 | F17: =COUNTIFS('Screen Status'!B2:B144,"Membership",'Screen Status'!G2:G144,"Not Started") -> 0 | G17: =COUNTIFS('Screen Status'!B2:B144,"Membership",'Screen Status'!G2:G144,"Upcoming (Dashboard)") -> 0 | H17: =COUNTIFS('Screen Status'!B2:B144,"Membership",'Screen Status'!G2:G144,"Upcoming (Config)") -> 0 | I17: =COUNTIFS('Screen Status'!B2:B144,"Membership",'Screen Status'!G2:G144,"Upcoming (Mobile)") -> 0 | J17: =COUNTIFS('Screen Status'!B2:B144,"Membership",'Screen Status'!G2:G144,"Upcoming") -> 0 | K17: =COUNTIF('Screen Status'!B2:B144,"Membership") -> 4
A18: Mobile | B18: =COUNTIFS('Screen Status'!B2:B144,"Mobile",'Screen Status'!G2:G144,"Completed") -> 0 | C18: =COUNTIFS('Screen Status'!B2:B144,"Mobile",'Screen Status'!G2:G144,"Completed - Needs Fix") -> 0 | D18: =COUNTIFS('Screen Status'!B2:B144,"Mobile",'Screen Status'!G2:G144,"Ready to Build") -> 0 | E18: =COUNTIFS('Screen Status'!B2:B144,"Mobile",'Screen Status'!G2:G144,"In Progress (Partial)") -> 0 | F18: =COUNTIFS('Screen Status'!B2:B144,"Mobile",'Screen Status'!G2:G144,"Not Started") -> 0 | G18: =COUNTIFS('Screen Status'!B2:B144,"Mobile",'Screen Status'!G2:G144,"Upcoming (Dashboard)") -> 0 | H18: =COUNTIFS('Screen Status'!B2:B144,"Mobile",'Screen Status'!G2:G144,"Upcoming (Config)") -> 0 | I18: =COUNTIFS('Screen Status'!B2:B144,"Mobile",'Screen Status'!G2:G144,"Upcoming (Mobile)") -> 1 | J18: =COUNTIFS('Screen Status'!B2:B144,"Mobile",'Screen Status'!G2:G144,"Upcoming") -> 0 | K18: =COUNTIF('Screen Status'!B2:B144,"Mobile") -> 1
A19: Organization | B19: =COUNTIFS('Screen Status'!B2:B144,"Organization",'Screen Status'!G2:G144,"Completed") -> 9 | C19: =COUNTIFS('Screen Status'!B2:B144,"Organization",'Screen Status'!G2:G144,"Completed - Needs Fix") -> 0 | D19: =COUNTIFS('Screen Status'!B2:B144,"Organization",'Screen Status'!G2:G144,"Ready to Build") -> 0 | E19: =COUNTIFS('Screen Status'!B2:B144,"Organization",'Screen Status'!G2:G144,"In Progress (Partial)") -> 0 | F19: =COUNTIFS('Screen Status'!B2:B144,"Organization",'Screen Status'!G2:G144,"Not Started") -> 1 | G19: =COUNTIFS('Screen Status'!B2:B144,"Organization",'Screen Status'!G2:G144,"Upcoming (Dashboard)") -> 0 | H19: =COUNTIFS('Screen Status'!B2:B144,"Organization",'Screen Status'!G2:G144,"Upcoming (Config)") -> 0 | I19: =COUNTIFS('Screen Status'!B2:B144,"Organization",'Screen Status'!G2:G144,"Upcoming (Mobile)") -> 0 | J19: =COUNTIFS('Screen Status'!B2:B144,"Organization",'Screen Status'!G2:G144,"Upcoming") -> 0 | K19: =COUNTIF('Screen Status'!B2:B144,"Organization") -> 10
A20: Reports | B20: =COUNTIFS('Screen Status'!B2:B144,"Reports",'Screen Status'!G2:G144,"Completed") -> 8 | C20: =COUNTIFS('Screen Status'!B2:B144,"Reports",'Screen Status'!G2:G144,"Completed - Needs Fix") -> 0 | D20: =COUNTIFS('Screen Status'!B2:B144,"Reports",'Screen Status'!G2:G144,"Ready to Build") -> 0 | E20: =COUNTIFS('Screen Status'!B2:B144,"Reports",'Screen Status'!G2:G144,"In Progress (Partial)") -> 0 | F20: =COUNTIFS('Screen Status'!B2:B144,"Reports",'Screen Status'!G2:G144,"Not Started") -> 0 | G20: =COUNTIFS('Screen Status'!B2:B144,"Reports",'Screen Status'!G2:G144,"Upcoming (Dashboard)") -> 0 | H20: =COUNTIFS('Screen Status'!B2:B144,"Reports",'Screen Status'!G2:G144,"Upcoming (Config)") -> 0 | I20: =COUNTIFS('Screen Status'!B2:B144,"Reports",'Screen Status'!G2:G144,"Upcoming (Mobile)") -> 0 | J20: =COUNTIFS('Screen Status'!B2:B144,"Reports",'Screen Status'!G2:G144,"Upcoming") -> 0 | K20: =COUNTIF('Screen Status'!B2:B144,"Reports") -> 8
A21: Root / Layout | B21: =COUNTIFS('Screen Status'!B2:B144,"Root / Layout",'Screen Status'!G2:G144,"Completed") -> 2 | C21: =COUNTIFS('Screen Status'!B2:B144,"Root / Layout",'Screen Status'!G2:G144,"Completed - Needs Fix") -> 0 | D21: =COUNTIFS('Screen Status'!B2:B144,"Root / Layout",'Screen Status'!G2:G144,"Ready to Build") -> 0 | E21: =COUNTIFS('Screen Status'!B2:B144,"Root / Layout",'Screen Status'!G2:G144,"In Progress (Partial)") -> 1 | F21: =COUNTIFS('Screen Status'!B2:B144,"Root / Layout",'Screen Status'!G2:G144,"Not Started") -> 0 | G21: =COUNTIFS('Screen Status'!B2:B144,"Root / Layout",'Screen Status'!G2:G144,"Upcoming (Dashboard)") -> 0 | H21: =COUNTIFS('Screen Status'!B2:B144,"Root / Layout",'Screen Status'!G2:G144,"Upcoming (Config)") -> 0 | I21: =COUNTIFS('Screen Status'!B2:B144,"Root / Layout",'Screen Status'!G2:G144,"Upcoming (Mobile)") -> 0 | J21: =COUNTIFS('Screen Status'!B2:B144,"Root / Layout",'Screen Status'!G2:G144,"Upcoming") -> 0 | K21: =COUNTIF('Screen Status'!B2:B144,"Root / Layout") -> 3
A22: Settings | B22: =COUNTIFS('Screen Status'!B2:B144,"Settings",'Screen Status'!G2:G144,"Completed") -> 20 | C22: =COUNTIFS('Screen Status'!B2:B144,"Settings",'Screen Status'!G2:G144,"Completed - Needs Fix") -> 0 | D22: =COUNTIFS('Screen Status'!B2:B144,"Settings",'Screen Status'!G2:G144,"Ready to Build") -> 0 | E22: =COUNTIFS('Screen Status'!B2:B144,"Settings",'Screen Status'!G2:G144,"In Progress (Partial)") -> 0 | F22: =COUNTIFS('Screen Status'!B2:B144,"Settings",'Screen Status'!G2:G144,"Not Started") -> 0 | G22: =COUNTIFS('Screen Status'!B2:B144,"Settings",'Screen Status'!G2:G144,"Upcoming (Dashboard)") -> 0 | H22: =COUNTIFS('Screen Status'!B2:B144,"Settings",'Screen Status'!G2:G144,"Upcoming (Config)") -> 0 | I22: =COUNTIFS('Screen Status'!B2:B144,"Settings",'Screen Status'!G2:G144,"Upcoming (Mobile)") -> 0 | J22: =COUNTIFS('Screen Status'!B2:B144,"Settings",'Screen Status'!G2:G144,"Upcoming") -> 0 | K22: =COUNTIF('Screen Status'!B2:B144,"Settings") -> 20
A23: Volunteer | B23: =COUNTIFS('Screen Status'!B2:B144,"Volunteer",'Screen Status'!G2:G144,"Completed") -> 4 | C23: =COUNTIFS('Screen Status'!B2:B144,"Volunteer",'Screen Status'!G2:G144,"Completed - Needs Fix") -> 0 | D23: =COUNTIFS('Screen Status'!B2:B144,"Volunteer",'Screen Status'!G2:G144,"Ready to Build") -> 0 | E23: =COUNTIFS('Screen Status'!B2:B144,"Volunteer",'Screen Status'!G2:G144,"In Progress (Partial)") -> 0 | F23: =COUNTIFS('Screen Status'!B2:B144,"Volunteer",'Screen Status'!G2:G144,"Not Started") -> 0 | G23: =COUNTIFS('Screen Status'!B2:B144,"Volunteer",'Screen Status'!G2:G144,"Upcoming (Dashboard)") -> 0 | H23: =COUNTIFS('Screen Status'!B2:B144,"Volunteer",'Screen Status'!G2:G144,"Upcoming (Config)") -> 0 | I23: =COUNTIFS('Screen Status'!B2:B144,"Volunteer",'Screen Status'!G2:G144,"Upcoming (Mobile)") -> 0 | J23: =COUNTIFS('Screen Status'!B2:B144,"Volunteer",'Screen Status'!G2:G144,"Upcoming") -> 0 | K23: =COUNTIF('Screen Status'!B2:B144,"Volunteer") -> 4
A24: Total | B24: =COUNTIF('Screen Status'!G2:G144,"Completed") -> 131 | C24: =COUNTIF('Screen Status'!G2:G144,"Completed - Needs Fix") -> 0 | D24: =COUNTIF('Screen Status'!G2:G144,"Ready to Build") -> 0 | E24: =COUNTIF('Screen Status'!G2:G144,"In Progress (Partial)") -> 1 | F24: =COUNTIF('Screen Status'!G2:G144,"Not Started") -> 1 | G24: =COUNTIF('Screen Status'!G2:G144,"Upcoming (Dashboard)") -> 0 | H24: =COUNTIF('Screen Status'!G2:G144,"Upcoming (Config)") -> 0 | I24: =COUNTIF('Screen Status'!G2:G144,"Upcoming (Mobile)") -> 1 | J24: =COUNTIF('Screen Status'!G2:G144,"Upcoming") -> 6 | K24: =COUNTA('Screen Status'!A2:A144) -> 140
A26: ② Testing Progress (Dev + QA)
A27: Module | B27: Dev: Not Started | C27: Dev: Pending | D27: Dev: In Testing | E27: Dev: Passed | F27: Dev: Failed | G27: Dev: Issues Found | H27: Dev: Blocked | I27: Dev: N/A | J27: QA: Not Started | K27: QA: Pending | L27: QA: In Testing | M27: QA: Passed | N27: QA: Failed | O27: QA: Issues Found | P27: QA: Blocked | Q27: QA: N/A
A28: AI Intelligence | B28: =COUNTIFS('Screen Status'!B2:B144,"AI Intelligence",'Screen Status'!J2:J144,"Not Started") -> 3 | C28: =COUNTIFS('Screen Status'!B2:B144,"AI Intelligence",'Screen Status'!J2:J144,"Pending") -> 0 | D28: =COUNTIFS('Screen Status'!B2:B144,"AI Intelligence",'Screen Status'!J2:J144,"In Testing") -> 0 | E28: =COUNTIFS('Screen Status'!B2:B144,"AI Intelligence",'Screen Status'!J2:J144,"Passed") -> 0 | F28: =COUNTIFS('Screen Status'!B2:B144,"AI Intelligence",'Screen Status'!J2:J144,"Failed") -> 0 | G28: =COUNTIFS('Screen Status'!B2:B144,"AI Intelligence",'Screen Status'!J2:J144,"Issues Found") -> 0 | H28: =COUNTIFS('Screen Status'!B2:B144,"AI Intelligence",'Screen Status'!J2:J144,"Blocked - Awaiting Fix") -> 0 | I28: =COUNTIFS('Screen Status'!B2:B144,"AI Intelligence",'Screen Status'!J2:J144,"N/A (Upcoming)") -> 3 | J28: =COUNTIFS('Screen Status'!B2:B144,"AI Intelligence",'Screen Status'!L2:L144,"Not Started") -> 0 | K28: =COUNTIFS('Screen Status'!B2:B144,"AI Intelligence",'Screen Status'!L2:L144,"Pending") -> 0 | L28: =COUNTIFS('Screen Status'!B2:B144,"AI Intelligence",'Screen Status'!L2:L144,"In Testing") -> 0 | M28: =COUNTIFS('Screen Status'!B2:B144,"AI Intelligence",'Screen Status'!L2:L144,"Passed") -> 0 | N28: =COUNTIFS('Screen Status'!B2:B144,"AI Intelligence",'Screen Status'!L2:L144,"Failed") -> 0 | O28: =COUNTIFS('Screen Status'!B2:B144,"AI Intelligence",'Screen Status'!L2:L144,"Issues Found") -> 0 | P28: =COUNTIFS('Screen Status'!B2:B144,"AI Intelligence",'Screen Status'!L2:L144,"Blocked - Awaiting Fix") -> 0 | Q28: =COUNTIFS('Screen Status'!B2:B144,"AI Intelligence",'Screen Status'!L2:L144,"N/A (Upcoming)") -> 0
A29: Administration | B29: =COUNTIFS('Screen Status'!B2:B144,"Administration",'Screen Status'!J2:J144,"Not Started") -> 6 | C29: =COUNTIFS('Screen Status'!B2:B144,"Administration",'Screen Status'!J2:J144,"Pending") -> 0 | D29: =COUNTIFS('Screen Status'!B2:B144,"Administration",'Screen Status'!J2:J144,"In Testing") -> 0 | E29: =COUNTIFS('Screen Status'!B2:B144,"Administration",'Screen Status'!J2:J144,"Passed") -> 0 | F29: =COUNTIFS('Screen Status'!B2:B144,"Administration",'Screen Status'!J2:J144,"Failed") -> 0 | G29: =COUNTIFS('Screen Status'!B2:B144,"Administration",'Screen Status'!J2:J144,"Issues Found") -> 0 | H29: =COUNTIFS('Screen Status'!B2:B144,"Administration",'Screen Status'!J2:J144,"Blocked - Awaiting Fix") -> 0 | I29: =COUNTIFS('Screen Status'!B2:B144,"Administration",'Screen Status'!J2:J144,"N/A (Upcoming)") -> 0 | J29: =COUNTIFS('Screen Status'!B2:B144,"Administration",'Screen Status'!L2:L144,"Not Started") -> 0 | K29: =COUNTIFS('Screen Status'!B2:B144,"Administration",'Screen Status'!L2:L144,"Pending") -> 0 | L29: =COUNTIFS('Screen Status'!B2:B144,"Administration",'Screen Status'!L2:L144,"In Testing") -> 0 | M29: =COUNTIFS('Screen Status'!B2:B144,"Administration",'Screen Status'!L2:L144,"Passed") -> 0 | N29: =COUNTIFS('Screen Status'!B2:B144,"Administration",'Screen Status'!L2:L144,"Failed") -> 0 | O29: =COUNTIFS('Screen Status'!B2:B144,"Administration",'Screen Status'!L2:L144,"Issues Found") -> 0 | P29: =COUNTIFS('Screen Status'!B2:B144,"Administration",'Screen Status'!L2:L144,"Blocked - Awaiting Fix") -> 0 | Q29: =COUNTIFS('Screen Status'!B2:B144,"Administration",'Screen Status'!L2:L144,"N/A (Upcoming)") -> 0
A30: Case Management | B30: =COUNTIFS('Screen Status'!B2:B144,"Case Management",'Screen Status'!J2:J144,"Not Started") -> 0 | C30: =COUNTIFS('Screen Status'!B2:B144,"Case Management",'Screen Status'!J2:J144,"Pending") -> 0 | D30: =COUNTIFS('Screen Status'!B2:B144,"Case Management",'Screen Status'!J2:J144,"In Testing") -> 0 | E30: =COUNTIFS('Screen Status'!B2:B144,"Case Management",'Screen Status'!J2:J144,"Passed") -> 3 | F30: =COUNTIFS('Screen Status'!B2:B144,"Case Management",'Screen Status'!J2:J144,"Failed") -> 0 | G30: =COUNTIFS('Screen Status'!B2:B144,"Case Management",'Screen Status'!J2:J144,"Issues Found") -> 0 | H30: =COUNTIFS('Screen Status'!B2:B144,"Case Management",'Screen Status'!J2:J144,"Blocked - Awaiting Fix") -> 0 | I30: =COUNTIFS('Screen Status'!B2:B144,"Case Management",'Screen Status'!J2:J144,"N/A (Upcoming)") -> 1 | J30: =COUNTIFS('Screen Status'!B2:B144,"Case Management",'Screen Status'!L2:L144,"Not Started") -> 0 | K30: =COUNTIFS('Screen Status'!B2:B144,"Case Management",'Screen Status'!L2:L144,"Pending") -> 0 | L30: =COUNTIFS('Screen Status'!B2:B144,"Case Management",'Screen Status'!L2:L144,"In Testing") -> 0 | M30: =COUNTIFS('Screen Status'!B2:B144,"Case Management",'Screen Status'!L2:L144,"Passed") -> 0 | N30: =COUNTIFS('Screen Status'!B2:B144,"Case Management",'Screen Status'!L2:L144,"Failed") -> 0 | O30: =COUNTIFS('Screen Status'!B2:B144,"Case Management",'Screen Status'!L2:L144,"Issues Found") -> 0 | P30: =COUNTIFS('Screen Status'!B2:B144,"Case Management",'Screen Status'!L2:L144,"Blocked - Awaiting Fix") -> 0 | Q30: =COUNTIFS('Screen Status'!B2:B144,"Case Management",'Screen Status'!L2:L144,"N/A (Upcoming)") -> 0
A31: Communication | B31: =COUNTIFS('Screen Status'!B2:B144,"Communication",'Screen Status'!J2:J144,"Not Started") -> 7 | C31: =COUNTIFS('Screen Status'!B2:B144,"Communication",'Screen Status'!J2:J144,"Pending") -> 1 | D31: =COUNTIFS('Screen Status'!B2:B144,"Communication",'Screen Status'!J2:J144,"In Testing") -> 1 | E31: =COUNTIFS('Screen Status'!B2:B144,"Communication",'Screen Status'!J2:J144,"Passed") -> 7 | F31: =COUNTIFS('Screen Status'!B2:B144,"Communication",'Screen Status'!J2:J144,"Failed") -> 0 | G31: =COUNTIFS('Screen Status'!B2:B144,"Communication",'Screen Status'!J2:J144,"Issues Found") -> 0 | H31: =COUNTIFS('Screen Status'!B2:B144,"Communication",'Screen Status'!J2:J144,"Blocked - Awaiting Fix") -> 0 | I31: =COUNTIFS('Screen Status'!B2:B144,"Communication",'Screen Status'!J2:J144,"N/A (Upcoming)") -> 0 | J31: =COUNTIFS('Screen Status'!B2:B144,"Communication",'Screen Status'!L2:L144,"Not Started") -> 0 | K31: =COUNTIFS('Screen Status'!B2:B144,"Communication",'Screen Status'!L2:L144,"Pending") -> 0 | L31: =COUNTIFS('Screen Status'!B2:B144,"Communication",'Screen Status'!L2:L144,"In Testing") -> 0 | M31: =COUNTIFS('Screen Status'!B2:B144,"Communication",'Screen Status'!L2:L144,"Passed") -> 0 | N31: =COUNTIFS('Screen Status'!B2:B144,"Communication",'Screen Status'!L2:L144,"Failed") -> 0 | O31: =COUNTIFS('Screen Status'!B2:B144,"Communication",'Screen Status'!L2:L144,"Issues Found") -> 0 | P31: =COUNTIFS('Screen Status'!B2:B144,"Communication",'Screen Status'!L2:L144,"Blocked - Awaiting Fix") -> 0 | Q31: =COUNTIFS('Screen Status'!B2:B144,"Communication",'Screen Status'!L2:L144,"N/A (Upcoming)") -> 0
A32: Contacts | B32: =COUNTIFS('Screen Status'!B2:B144,"Contacts",'Screen Status'!J2:J144,"Not Started") -> 1 | C32: =COUNTIFS('Screen Status'!B2:B144,"Contacts",'Screen Status'!J2:J144,"Pending") -> 1 | D32: =COUNTIFS('Screen Status'!B2:B144,"Contacts",'Screen Status'!J2:J144,"In Testing") -> 0 | E32: =COUNTIFS('Screen Status'!B2:B144,"Contacts",'Screen Status'!J2:J144,"Passed") -> 6 | F32: =COUNTIFS('Screen Status'!B2:B144,"Contacts",'Screen Status'!J2:J144,"Failed") -> 0 | G32: =COUNTIFS('Screen Status'!B2:B144,"Contacts",'Screen Status'!J2:J144,"Issues Found") -> 0 | H32: =COUNTIFS('Screen Status'!B2:B144,"Contacts",'Screen Status'!J2:J144,"Blocked - Awaiting Fix") -> 0 | I32: =COUNTIFS('Screen Status'!B2:B144,"Contacts",'Screen Status'!J2:J144,"N/A (Upcoming)") -> 0 | J32: =COUNTIFS('Screen Status'!B2:B144,"Contacts",'Screen Status'!L2:L144,"Not Started") -> 0 | K32: =COUNTIFS('Screen Status'!B2:B144,"Contacts",'Screen Status'!L2:L144,"Pending") -> 0 | L32: =COUNTIFS('Screen Status'!B2:B144,"Contacts",'Screen Status'!L2:L144,"In Testing") -> 0 | M32: =COUNTIFS('Screen Status'!B2:B144,"Contacts",'Screen Status'!L2:L144,"Passed") -> 0 | N32: =COUNTIFS('Screen Status'!B2:B144,"Contacts",'Screen Status'!L2:L144,"Failed") -> 0 | O32: =COUNTIFS('Screen Status'!B2:B144,"Contacts",'Screen Status'!L2:L144,"Issues Found") -> 0 | P32: =COUNTIFS('Screen Status'!B2:B144,"Contacts",'Screen Status'!L2:L144,"Blocked - Awaiting Fix") -> 0 | Q32: =COUNTIFS('Screen Status'!B2:B144,"Contacts",'Screen Status'!L2:L144,"N/A (Upcoming)") -> 0
A33: Field Collection | B33: =COUNTIFS('Screen Status'!B2:B144,"Field Collection",'Screen Status'!J2:J144,"Not Started") -> 2 | C33: =COUNTIFS('Screen Status'!B2:B144,"Field Collection",'Screen Status'!J2:J144,"Pending") -> 3 | D33: =COUNTIFS('Screen Status'!B2:B144,"Field Collection",'Screen Status'!J2:J144,"In Testing") -> 0 | E33: =COUNTIFS('Screen Status'!B2:B144,"Field Collection",'Screen Status'!J2:J144,"Passed") -> 0 | F33: =COUNTIFS('Screen Status'!B2:B144,"Field Collection",'Screen Status'!J2:J144,"Failed") -> 0 | G33: =COUNTIFS('Screen Status'!B2:B144,"Field Collection",'Screen Status'!J2:J144,"Issues Found") -> 0 | H33: =COUNTIFS('Screen Status'!B2:B144,"Field Collection",'Screen Status'!J2:J144,"Blocked - Awaiting Fix") -> 0 | I33: =COUNTIFS('Screen Status'!B2:B144,"Field Collection",'Screen Status'!J2:J144,"N/A (Upcoming)") -> 1 | J33: =COUNTIFS('Screen Status'!B2:B144,"Field Collection",'Screen Status'!L2:L144,"Not Started") -> 0 | K33: =COUNTIFS('Screen Status'!B2:B144,"Field Collection",'Screen Status'!L2:L144,"Pending") -> 0 | L33: =COUNTIFS('Screen Status'!B2:B144,"Field Collection",'Screen Status'!L2:L144,"In Testing") -> 0 | M33: =COUNTIFS('Screen Status'!B2:B144,"Field Collection",'Screen Status'!L2:L144,"Passed") -> 0 | N33: =COUNTIFS('Screen Status'!B2:B144,"Field Collection",'Screen Status'!L2:L144,"Failed") -> 0 | O33: =COUNTIFS('Screen Status'!B2:B144,"Field Collection",'Screen Status'!L2:L144,"Issues Found") -> 0 | P33: =COUNTIFS('Screen Status'!B2:B144,"Field Collection",'Screen Status'!L2:L144,"Blocked - Awaiting Fix") -> 0 | Q33: =COUNTIFS('Screen Status'!B2:B144,"Field Collection",'Screen Status'!L2:L144,"N/A (Upcoming)") -> 0
A34: Fundraising | B34: =COUNTIFS('Screen Status'!B2:B144,"Fundraising",'Screen Status'!J2:J144,"Not Started") -> 3 | C34: =COUNTIFS('Screen Status'!B2:B144,"Fundraising",'Screen Status'!J2:J144,"Pending") -> 3 | D34: =COUNTIFS('Screen Status'!B2:B144,"Fundraising",'Screen Status'!J2:J144,"In Testing") -> 1 | E34: =COUNTIFS('Screen Status'!B2:B144,"Fundraising",'Screen Status'!J2:J144,"Passed") -> 11 | F34: =COUNTIFS('Screen Status'!B2:B144,"Fundraising",'Screen Status'!J2:J144,"Failed") -> 0 | G34: =COUNTIFS('Screen Status'!B2:B144,"Fundraising",'Screen Status'!J2:J144,"Issues Found") -> 0 | H34: =COUNTIFS('Screen Status'!B2:B144,"Fundraising",'Screen Status'!J2:J144,"Blocked - Awaiting Fix") -> 0 | I34: =COUNTIFS('Screen Status'!B2:B144,"Fundraising",'Screen Status'!J2:J144,"N/A (Upcoming)") -> 0 | J34: =COUNTIFS('Screen Status'!B2:B144,"Fundraising",'Screen Status'!L2:L144,"Not Started") -> 0 | K34: =COUNTIFS('Screen Status'!B2:B144,"Fundraising",'Screen Status'!L2:L144,"Pending") -> 0 | L34: =COUNTIFS('Screen Status'!B2:B144,"Fundraising",'Screen Status'!L2:L144,"In Testing") -> 0 | M34: =COUNTIFS('Screen Status'!B2:B144,"Fundraising",'Screen Status'!L2:L144,"Passed") -> 0 | N34: =COUNTIFS('Screen Status'!B2:B144,"Fundraising",'Screen Status'!L2:L144,"Failed") -> 0 | O34: =COUNTIFS('Screen Status'!B2:B144,"Fundraising",'Screen Status'!L2:L144,"Issues Found") -> 0 | P34: =COUNTIFS('Screen Status'!B2:B144,"Fundraising",'Screen Status'!L2:L144,"Blocked - Awaiting Fix") -> 0 | Q34: =COUNTIFS('Screen Status'!B2:B144,"Fundraising",'Screen Status'!L2:L144,"N/A (Upcoming)") -> 0
A35: Grants | B35: =COUNTIFS('Screen Status'!B2:B144,"Grants",'Screen Status'!J2:J144,"Not Started") -> 0 | C35: =COUNTIFS('Screen Status'!B2:B144,"Grants",'Screen Status'!J2:J144,"Pending") -> 0 | D35: =COUNTIFS('Screen Status'!B2:B144,"Grants",'Screen Status'!J2:J144,"In Testing") -> 0 | E35: =COUNTIFS('Screen Status'!B2:B144,"Grants",'Screen Status'!J2:J144,"Passed") -> 3 | F35: =COUNTIFS('Screen Status'!B2:B144,"Grants",'Screen Status'!J2:J144,"Failed") -> 0 | G35: =COUNTIFS('Screen Status'!B2:B144,"Grants",'Screen Status'!J2:J144,"Issues Found") -> 0 | H35: =COUNTIFS('Screen Status'!B2:B144,"Grants",'Screen Status'!J2:J144,"Blocked - Awaiting Fix") -> 0 | I35: =COUNTIFS('Screen Status'!B2:B144,"Grants",'Screen Status'!J2:J144,"N/A (Upcoming)") -> 0 | J35: =COUNTIFS('Screen Status'!B2:B144,"Grants",'Screen Status'!L2:L144,"Not Started") -> 0 | K35: =COUNTIFS('Screen Status'!B2:B144,"Grants",'Screen Status'!L2:L144,"Pending") -> 0 | L35: =COUNTIFS('Screen Status'!B2:B144,"Grants",'Screen Status'!L2:L144,"In Testing") -> 0 | M35: =COUNTIFS('Screen Status'!B2:B144,"Grants",'Screen Status'!L2:L144,"Passed") -> 0 | N35: =COUNTIFS('Screen Status'!B2:B144,"Grants",'Screen Status'!L2:L144,"Failed") -> 0 | O35: =COUNTIFS('Screen Status'!B2:B144,"Grants",'Screen Status'!L2:L144,"Issues Found") -> 0 | P35: =COUNTIFS('Screen Status'!B2:B144,"Grants",'Screen Status'!L2:L144,"Blocked - Awaiting Fix") -> 0 | Q35: =COUNTIFS('Screen Status'!B2:B144,"Grants",'Screen Status'!L2:L144,"N/A (Upcoming)") -> 0
A36: Membership | B36: =COUNTIFS('Screen Status'!B2:B144,"Membership",'Screen Status'!J2:J144,"Not Started") -> 0 | C36: =COUNTIFS('Screen Status'!B2:B144,"Membership",'Screen Status'!J2:J144,"Pending") -> 0 | D36: =COUNTIFS('Screen Status'!B2:B144,"Membership",'Screen Status'!J2:J144,"In Testing") -> 1 | E36: =COUNTIFS('Screen Status'!B2:B144,"Membership",'Screen Status'!J2:J144,"Passed") -> 2 | F36: =COUNTIFS('Screen Status'!B2:B144,"Membership",'Screen Status'!J2:J144,"Failed") -> 0 | G36: =COUNTIFS('Screen Status'!B2:B144,"Membership",'Screen Status'!J2:J144,"Issues Found") -> 0 | H36: =COUNTIFS('Screen Status'!B2:B144,"Membership",'Screen Status'!J2:J144,"Blocked - Awaiting Fix") -> 0 | I36: =COUNTIFS('Screen Status'!B2:B144,"Membership",'Screen Status'!J2:J144,"N/A (Upcoming)") -> 0 | J36: =COUNTIFS('Screen Status'!B2:B144,"Membership",'Screen Status'!L2:L144,"Not Started") -> 0 | K36: =COUNTIFS('Screen Status'!B2:B144,"Membership",'Screen Status'!L2:L144,"Pending") -> 0 | L36: =COUNTIFS('Screen Status'!B2:B144,"Membership",'Screen Status'!L2:L144,"In Testing") -> 0 | M36: =COUNTIFS('Screen Status'!B2:B144,"Membership",'Screen Status'!L2:L144,"Passed") -> 0 | N36: =COUNTIFS('Screen Status'!B2:B144,"Membership",'Screen Status'!L2:L144,"Failed") -> 0 | O36: =COUNTIFS('Screen Status'!B2:B144,"Membership",'Screen Status'!L2:L144,"Issues Found") -> 0 | P36: =COUNTIFS('Screen Status'!B2:B144,"Membership",'Screen Status'!L2:L144,"Blocked - Awaiting Fix") -> 0 | Q36: =COUNTIFS('Screen Status'!B2:B144,"Membership",'Screen Status'!L2:L144,"N/A (Upcoming)") -> 0
A37: Mobile | B37: =COUNTIFS('Screen Status'!B2:B144,"Mobile",'Screen Status'!J2:J144,"Not Started") -> 0 | C37: =COUNTIFS('Screen Status'!B2:B144,"Mobile",'Screen Status'!J2:J144,"Pending") -> 0 | D37: =COUNTIFS('Screen Status'!B2:B144,"Mobile",'Screen Status'!J2:J144,"In Testing") -> 0 | E37: =COUNTIFS('Screen Status'!B2:B144,"Mobile",'Screen Status'!J2:J144,"Passed") -> 0 | F37: =COUNTIFS('Screen Status'!B2:B144,"Mobile",'Screen Status'!J2:J144,"Failed") -> 0 | G37: =COUNTIFS('Screen Status'!B2:B144,"Mobile",'Screen Status'!J2:J144,"Issues Found") -> 0 | H37: =COUNTIFS('Screen Status'!B2:B144,"Mobile",'Screen Status'!J2:J144,"Blocked - Awaiting Fix") -> 0 | I37: =COUNTIFS('Screen Status'!B2:B144,"Mobile",'Screen Status'!J2:J144,"N/A (Upcoming)") -> 1 | J37: =COUNTIFS('Screen Status'!B2:B144,"Mobile",'Screen Status'!L2:L144,"Not Started") -> 0 | K37: =COUNTIFS('Screen Status'!B2:B144,"Mobile",'Screen Status'!L2:L144,"Pending") -> 0 | L37: =COUNTIFS('Screen Status'!B2:B144,"Mobile",'Screen Status'!L2:L144,"In Testing") -> 0 | M37: =COUNTIFS('Screen Status'!B2:B144,"Mobile",'Screen Status'!L2:L144,"Passed") -> 0 | N37: =COUNTIFS('Screen Status'!B2:B144,"Mobile",'Screen Status'!L2:L144,"Failed") -> 0 | O37: =COUNTIFS('Screen Status'!B2:B144,"Mobile",'Screen Status'!L2:L144,"Issues Found") -> 0 | P37: =COUNTIFS('Screen Status'!B2:B144,"Mobile",'Screen Status'!L2:L144,"Blocked - Awaiting Fix") -> 0 | Q37: =COUNTIFS('Screen Status'!B2:B144,"Mobile",'Screen Status'!L2:L144,"N/A (Upcoming)") -> 0
A38: Organization | B38: =COUNTIFS('Screen Status'!B2:B144,"Organization",'Screen Status'!J2:J144,"Not Started") -> 2 | C38: =COUNTIFS('Screen Status'!B2:B144,"Organization",'Screen Status'!J2:J144,"Pending") -> 1 | D38: =COUNTIFS('Screen Status'!B2:B144,"Organization",'Screen Status'!J2:J144,"In Testing") -> 0 | E38: =COUNTIFS('Screen Status'!B2:B144,"Organization",'Screen Status'!J2:J144,"Passed") -> 7 | F38: =COUNTIFS('Screen Status'!B2:B144,"Organization",'Screen Status'!J2:J144,"Failed") -> 0 | G38: =COUNTIFS('Screen Status'!B2:B144,"Organization",'Screen Status'!J2:J144,"Issues Found") -> 0 | H38: =COUNTIFS('Screen Status'!B2:B144,"Organization",'Screen Status'!J2:J144,"Blocked - Awaiting Fix") -> 0 | I38: =COUNTIFS('Screen Status'!B2:B144,"Organization",'Screen Status'!J2:J144,"N/A (Upcoming)") -> 0 | J38: =COUNTIFS('Screen Status'!B2:B144,"Organization",'Screen Status'!L2:L144,"Not Started") -> 0 | K38: =COUNTIFS('Screen Status'!B2:B144,"Organization",'Screen Status'!L2:L144,"Pending") -> 0 | L38: =COUNTIFS('Screen Status'!B2:B144,"Organization",'Screen Status'!L2:L144,"In Testing") -> 0 | M38: =COUNTIFS('Screen Status'!B2:B144,"Organization",'Screen Status'!L2:L144,"Passed") -> 0 | N38: =COUNTIFS('Screen Status'!B2:B144,"Organization",'Screen Status'!L2:L144,"Failed") -> 0 | O38: =COUNTIFS('Screen Status'!B2:B144,"Organization",'Screen Status'!L2:L144,"Issues Found") -> 0 | P38: =COUNTIFS('Screen Status'!B2:B144,"Organization",'Screen Status'!L2:L144,"Blocked - Awaiting Fix") -> 0 | Q38: =COUNTIFS('Screen Status'!B2:B144,"Organization",'Screen Status'!L2:L144,"N/A (Upcoming)") -> 0
A39: Reports | B39: =COUNTIFS('Screen Status'!B2:B144,"Reports",'Screen Status'!J2:J144,"Not Started") -> 4 | C39: =COUNTIFS('Screen Status'!B2:B144,"Reports",'Screen Status'!J2:J144,"Pending") -> 0 | D39: =COUNTIFS('Screen Status'!B2:B144,"Reports",'Screen Status'!J2:J144,"In Testing") -> 0 | E39: =COUNTIFS('Screen Status'!B2:B144,"Reports",'Screen Status'!J2:J144,"Passed") -> 0 | F39: =COUNTIFS('Screen Status'!B2:B144,"Reports",'Screen Status'!J2:J144,"Failed") -> 0 | G39: =COUNTIFS('Screen Status'!B2:B144,"Reports",'Screen Status'!J2:J144,"Issues Found") -> 0 | H39: =COUNTIFS('Screen Status'!B2:B144,"Reports",'Screen Status'!J2:J144,"Blocked - Awaiting Fix") -> 0 | I39: =COUNTIFS('Screen Status'!B2:B144,"Reports",'Screen Status'!J2:J144,"N/A (Upcoming)") -> 4 | J39: =COUNTIFS('Screen Status'!B2:B144,"Reports",'Screen Status'!L2:L144,"Not Started") -> 0 | K39: =COUNTIFS('Screen Status'!B2:B144,"Reports",'Screen Status'!L2:L144,"Pending") -> 0 | L39: =COUNTIFS('Screen Status'!B2:B144,"Reports",'Screen Status'!L2:L144,"In Testing") -> 0 | M39: =COUNTIFS('Screen Status'!B2:B144,"Reports",'Screen Status'!L2:L144,"Passed") -> 0 | N39: =COUNTIFS('Screen Status'!B2:B144,"Reports",'Screen Status'!L2:L144,"Failed") -> 0 | O39: =COUNTIFS('Screen Status'!B2:B144,"Reports",'Screen Status'!L2:L144,"Issues Found") -> 0 | P39: =COUNTIFS('Screen Status'!B2:B144,"Reports",'Screen Status'!L2:L144,"Blocked - Awaiting Fix") -> 0 | Q39: =COUNTIFS('Screen Status'!B2:B144,"Reports",'Screen Status'!L2:L144,"N/A (Upcoming)") -> 0
A40: Root / Layout | B40: =COUNTIFS('Screen Status'!B2:B144,"Root / Layout",'Screen Status'!J2:J144,"Not Started") -> 3 | C40: =COUNTIFS('Screen Status'!B2:B144,"Root / Layout",'Screen Status'!J2:J144,"Pending") -> 0 | D40: =COUNTIFS('Screen Status'!B2:B144,"Root / Layout",'Screen Status'!J2:J144,"In Testing") -> 0 | E40: =COUNTIFS('Screen Status'!B2:B144,"Root / Layout",'Screen Status'!J2:J144,"Passed") -> 0 | F40: =COUNTIFS('Screen Status'!B2:B144,"Root / Layout",'Screen Status'!J2:J144,"Failed") -> 0 | G40: =COUNTIFS('Screen Status'!B2:B144,"Root / Layout",'Screen Status'!J2:J144,"Issues Found") -> 0 | H40: =COUNTIFS('Screen Status'!B2:B144,"Root / Layout",'Screen Status'!J2:J144,"Blocked - Awaiting Fix") -> 0 | I40: =COUNTIFS('Screen Status'!B2:B144,"Root / Layout",'Screen Status'!J2:J144,"N/A (Upcoming)") -> 0 | J40: =COUNTIFS('Screen Status'!B2:B144,"Root / Layout",'Screen Status'!L2:L144,"Not Started") -> 0 | K40: =COUNTIFS('Screen Status'!B2:B144,"Root / Layout",'Screen Status'!L2:L144,"Pending") -> 0 | L40: =COUNTIFS('Screen Status'!B2:B144,"Root / Layout",'Screen Status'!L2:L144,"In Testing") -> 0 | M40: =COUNTIFS('Screen Status'!B2:B144,"Root / Layout",'Screen Status'!L2:L144,"Passed") -> 0 | N40: =COUNTIFS('Screen Status'!B2:B144,"Root / Layout",'Screen Status'!L2:L144,"Failed") -> 0 | O40: =COUNTIFS('Screen Status'!B2:B144,"Root / Layout",'Screen Status'!L2:L144,"Issues Found") -> 0 | P40: =COUNTIFS('Screen Status'!B2:B144,"Root / Layout",'Screen Status'!L2:L144,"Blocked - Awaiting Fix") -> 0 | Q40: =COUNTIFS('Screen Status'!B2:B144,"Root / Layout",'Screen Status'!L2:L144,"N/A (Upcoming)") -> 0
A41: Settings | B41: =COUNTIFS('Screen Status'!B2:B144,"Settings",'Screen Status'!J2:J144,"Not Started") -> 13 | C41: =COUNTIFS('Screen Status'!B2:B144,"Settings",'Screen Status'!J2:J144,"Pending") -> 0 | D41: =COUNTIFS('Screen Status'!B2:B144,"Settings",'Screen Status'!J2:J144,"In Testing") -> 1 | E41: =COUNTIFS('Screen Status'!B2:B144,"Settings",'Screen Status'!J2:J144,"Passed") -> 2 | F41: =COUNTIFS('Screen Status'!B2:B144,"Settings",'Screen Status'!J2:J144,"Failed") -> 0 | G41: =COUNTIFS('Screen Status'!B2:B144,"Settings",'Screen Status'!J2:J144,"Issues Found") -> 0 | H41: =COUNTIFS('Screen Status'!B2:B144,"Settings",'Screen Status'!J2:J144,"Blocked - Awaiting Fix") -> 0 | I41: =COUNTIFS('Screen Status'!B2:B144,"Settings",'Screen Status'!J2:J144,"N/A (Upcoming)") -> 4 | J41: =COUNTIFS('Screen Status'!B2:B144,"Settings",'Screen Status'!L2:L144,"Not Started") -> 0 | K41: =COUNTIFS('Screen Status'!B2:B144,"Settings",'Screen Status'!L2:L144,"Pending") -> 0 | L41: =COUNTIFS('Screen Status'!B2:B144,"Settings",'Screen Status'!L2:L144,"In Testing") -> 0 | M41: =COUNTIFS('Screen Status'!B2:B144,"Settings",'Screen Status'!L2:L144,"Passed") -> 0 | N41: =COUNTIFS('Screen Status'!B2:B144,"Settings",'Screen Status'!L2:L144,"Failed") -> 0 | O41: =COUNTIFS('Screen Status'!B2:B144,"Settings",'Screen Status'!L2:L144,"Issues Found") -> 0 | P41: =COUNTIFS('Screen Status'!B2:B144,"Settings",'Screen Status'!L2:L144,"Blocked - Awaiting Fix") -> 0 | Q41: =COUNTIFS('Screen Status'!B2:B144,"Settings",'Screen Status'!L2:L144,"N/A (Upcoming)") -> 0
A42: Volunteer | B42: =COUNTIFS('Screen Status'!B2:B144,"Volunteer",'Screen Status'!J2:J144,"Not Started") -> 0 | C42: =COUNTIFS('Screen Status'!B2:B144,"Volunteer",'Screen Status'!J2:J144,"Pending") -> 0 | D42: =COUNTIFS('Screen Status'!B2:B144,"Volunteer",'Screen Status'!J2:J144,"In Testing") -> 0 | E42: =COUNTIFS('Screen Status'!B2:B144,"Volunteer",'Screen Status'!J2:J144,"Passed") -> 3 | F42: =COUNTIFS('Screen Status'!B2:B144,"Volunteer",'Screen Status'!J2:J144,"Failed") -> 0 | G42: =COUNTIFS('Screen Status'!B2:B144,"Volunteer",'Screen Status'!J2:J144,"Issues Found") -> 0 | H42: =COUNTIFS('Screen Status'!B2:B144,"Volunteer",'Screen Status'!J2:J144,"Blocked - Awaiting Fix") -> 0 | I42: =COUNTIFS('Screen Status'!B2:B144,"Volunteer",'Screen Status'!J2:J144,"N/A (Upcoming)") -> 1 | J42: =COUNTIFS('Screen Status'!B2:B144,"Volunteer",'Screen Status'!L2:L144,"Not Started") -> 0 | K42: =COUNTIFS('Screen Status'!B2:B144,"Volunteer",'Screen Status'!L2:L144,"Pending") -> 0 | L42: =COUNTIFS('Screen Status'!B2:B144,"Volunteer",'Screen Status'!L2:L144,"In Testing") -> 0 | M42: =COUNTIFS('Screen Status'!B2:B144,"Volunteer",'Screen Status'!L2:L144,"Passed") -> 0 | N42: =COUNTIFS('Screen Status'!B2:B144,"Volunteer",'Screen Status'!L2:L144,"Failed") -> 0 | O42: =COUNTIFS('Screen Status'!B2:B144,"Volunteer",'Screen Status'!L2:L144,"Issues Found") -> 0 | P42: =COUNTIFS('Screen Status'!B2:B144,"Volunteer",'Screen Status'!L2:L144,"Blocked - Awaiting Fix") -> 0 | Q42: =COUNTIFS('Screen Status'!B2:B144,"Volunteer",'Screen Status'!L2:L144,"N/A (Upcoming)") -> 0
A43: Total | B43: =COUNTIF('Screen Status'!J2:J144,"Not Started") -> 49 | C43: =COUNTIF('Screen Status'!J2:J144,"Pending") -> 9 | D43: =COUNTIF('Screen Status'!J2:J144,"In Testing") -> 4 | E43: =COUNTIF('Screen Status'!J2:J144,"Passed") -> 61 | F43: =COUNTIF('Screen Status'!J2:J144,"Failed") -> 0 | G43: =COUNTIF('Screen Status'!J2:J144,"Issues Found") -> 0 | H43: =COUNTIF('Screen Status'!J2:J144,"Blocked - Awaiting Fix") -> 0 | I43: =COUNTIF('Screen Status'!J2:J144,"N/A (Upcoming)") -> 15 | J43: =COUNTIF('Screen Status'!L2:L144,"Not Started") -> 0 | K43: =COUNTIF('Screen Status'!L2:L144,"Pending") -> 0 | L43: =COUNTIF('Screen Status'!L2:L144,"In Testing") -> 0 | M43: =COUNTIF('Screen Status'!L2:L144,"Passed") -> 0 | N43: =COUNTIF('Screen Status'!L2:L144,"Failed") -> 0 | O43: =COUNTIF('Screen Status'!L2:L144,"Issues Found") -> 0 | P43: =COUNTIF('Screen Status'!L2:L144,"Blocked - Awaiting Fix") -> 0 | Q43: =COUNTIF('Screen Status'!L2:L144,"N/A (Upcoming)") -> 0
...

Sheet Dev Test Cases
A1: ① Test Cases
A2: Case Level | B2: Case Title | C2: Case Description
A3: Basic | B3: CRUD | C3: Need to test crud operations (add, edit, delete, toggle)
A4: Basic | B4: Search

Sheet Your Pending List
A1: PSS 2.0 — Your Pending List (from Pending.txt)
A2: YOUR list — items you noted in Pending.txt, reworded as clear work items. Estimated hours = ONE developer WITH AI assistance at AVERAGE prompting skill (includes prompt iteration, reviewing/fixing AI output, and testing). ~6 productive hrs = 1 day.
A4: SUMMARY
A5: Source | B5: Items | C5: Dev Hrs | D5: Test Hrs | E5: Total Hrs
A6: Pending.txt | B6: 39 | C6: 260 | D6: 167 | E6: 427
A7: TOTAL | B7: 39 | C7: 260 | D7: 167 | E7: 427
A8: ≈ 427 total hours · ~71.2 working days for 1 AI-assisted developer (avg prompter)
A10: ID | B10: Source | C10: Module | D10: Screen / Area | E10: Work Item | F10: Type | G10: Priority | H10: Tracker Status | I10: Dev Hrs (AI) | J10: Test/Verify Hrs | K10: Total Hrs | L10: Notes / Approach
A11: 1 | B11: Pending.txt | C11: Fundraising / Contacts | D11: Currency handling (contact + amount display) | E11: Complete multi-currency handling in the remaining areas — contact-level currency, and every amount-display surface (grids, tiles, receipts, detail drawers) that still shows raw/base amounts. | F11: Cross-cutting | G11: High | H11: Partially done | I11: 12 | J11: 5 | K11: 17 | L11: Sweep all screens; reuse existing currency formatter; verify per-record currency vs org base.
A12: 2 | B12: Pending.txt | C12: Global | D12: Currency conversion rate coverage | E12: Apply currency conversion-rate handling consistently across ALL areas that show or roll-up amounts (dashboards, reports, reconciliations). | F12: Cross-cutting | G12: High | H12: Partially done | I12: 10 | J12: 4 | K12: 14 | L12: Use direct-pair FX only (no USD triangulation); snapshot rate value on transaction rows.
A13: 3 | B13: Pending.txt | C13: Global | D13: Currency decimal format | E13: Standardise currency decimal formatting (precision, grouping, symbol placement) across all input and display areas. | F13: Cross-cutting | G13: Medium | H13: Partially done | I13: 6 | J13: 3 | K13: 9 | L13: Central format util; drive precision from currency master.
A14: 4 | B14: Pending.txt | C14: Global | D14: Timezone handling | E14: Implement end-to-end timezone handling — store UTC, display in org/user timezone across all date fields, filters and reports. | F14: Cross-cutting | G14: High | H14: Not started | I14: 12 | J14: 5 | K14: 17 | L14: DB is timestamptz; normalise wire DTOs; avoid DateTime.Today in EF predicates.
A15: 5 | B15: Pending.txt | C15: Contacts | D15: Contact Import | E15: Re-test Contact Import end-to-end (mapping, dedupe on import, error rows, large-file). | F15: Retest | G15: Medium | H15: Marked Completed | I15: 1 | J15: 4 | K15: 5 | L15: Business-flow retest; confirm duplicate handling on import.
A16: 6 | B16: Pending.txt | C16: Contacts | D16: Family | E16: Re-test Family screen (relationships, primary contact, merge behaviour). | F16: Retest | G16: Medium | H16: Marked Completed | I16: 1 | J16: 3 | K16: 4 | L16: Business-flow retest.
A17: 7 | B17: Pending.txt | C17: Global | D17: Grids — import & toggle cleanup | E17: Remove the Import action and the show/hide toggle option from all grids except the grids where they are genuinely required. | F17: Fix – UI/UX | G17: Medium | H17: Marked Completed | I17: 4 | J17: 2 | K17: 6 | L17: Audit each grid config; keep import only where a real import flow exists.
A18: 8 | B18: Pending.txt | C18: Contacts | D18: Duplicate Detection | E18: Re-test Duplicate Detection (match rules, merge, survivorship). | F18: Retest | G18: Medium | H18: Marked Completed | I18: 1 | J18: 3 | K18: 4 | L18: Business-flow retest.
A19: 9 | B19: Pending.txt | C19: Certificate | D19: Certificate Processing | E19: Re-test Certificate processing screen (generation, print, template binding). | F19: Retest | G19: Medium | H19: Marked Completed | I19: 1 | J19: 3 | K19: 4 | L19: Business-flow retest.
A20: 10 | B20: Pending.txt | C20: Fundraising | D20: Pledge | E20: Reconcile Pledge screen — tracker says Completed but Pending list flags it for development; finish gaps and verify full pledge lifecycle (schedule, fulfilment, write-off). | F20: Complete/Verify | G20: High | H20: Marked Completed (disputed) | I20: 6 | J20: 3 | K20: 9 | L20: Confirm what is missing vs. built; close gaps.
A21: 11 | B21: Pending.txt | C21: Fundraising | D21: Bulk Donation Upload | E21: Complete & re-test bulk donation upload (template, validation, partial-failure, receipting). | F21: Complete/Retest | G21: Medium | H21: Marked Completed | I21: 4 | J21: 3 | K21: 7 | L21: Verify large-file + error-row handling.
A22: 12 | B22: Pending.txt | C22: Fundraising | D22: Donation Reconciliation | E22: Complete & re-test donation/payment reconciliation (matching, unmatched queue, gateway settlement). | F22: Complete/Retest | G22: High | H22: Marked Completed | I22: 4 | J22: 3 | K22: 7 | L22: Ties to payment-gateway real integration.
... A49: 39 | B49: Pending.txt | C49: Settings | D49: Settings hierarchy config | E49: Complete Setting Group + Organization Setting + User Setting hierarchy configuration screen (inheritance/override). | F49: Complete/Verify | G49: Medium | H49: Marked Completed | I49: 6 | J49: 3 | K49: 9 | L49: Verify override precedence.

Sheet My Review Findings
A1: PSS 2.0 — My Review Findings (Gap Analysis + Code Audit)
A2: MY list — items I found in review: Gap Analysis (missing flows/integrations, e.g. grant creation flow, communication service integration) + Code Audit (335 findings from PRODUCTION-READINESS-BACKLOG.md). Same estimation basis: 1 AI-assisted developer, average prompter. ~6 productive hrs = 1 day.
A4: SUMMARY
A5: Source | B5: Items | C5: Dev Hrs | D5: Test Hrs | E5: Total Hrs
A6: Gap Analysis | B6: 15 | C6: 77 | D6: 40 | E6: 117
A7: Code Audit | B7: 335 | C7: 846.5 | D7: 423.25 | E7: 1269.75
A8: TOTAL | B8: 350 | C8: 923.5 | D8: 463.25 | E8: 1386.75
A9: ≈ 1386.8 total hours · ~231.1 working days for 1 AI-assisted developer (avg prompter)
A11: ID | B11: Source | C11: Module | D11: Screen / Area | E11: Work Item | F11: Type | G11: Priority | H11: Tracker Status | I11: Dev Hrs (AI) | J11: Test/Verify Hrs | K11: Total Hrs | L11: Notes / Approach
A12: 1 | B12: Gap Analysis | C12: Grants | D12: Grant | E12: Grant creation flow — missing/incomplete steps: creation does not enforce the full application intake (funder, award-letter evidence, budget lines) before it can advance. | F12: Gap – Flow | G12: High | H12: Discovered | I12: 6 | J12: 3 | K12: 9 | L12: Align create → submit → approve with lifecycle rules.
A13: 2 | B13: Gap Analysis | C13: Grants | D13: Grant | E13: Communication service integration missing on Grant screen — funder communication (compose-from-template + auto internal notify) not wired into the grant lifecycle actions. | F13: Gap – Integration | G13: High | H13: Discovered | I13: 5 | J13: 3 | K13: 8 | L13: Wire SendComposedEmail + GrantCommunication audit tab.
A14: 3 | B14: Gap Analysis | C14: Grants | D14: Grant Stage | E14: Stage transition bypasses approval rules — a generic stage-mover can move a grant to Approved without award-letter evidence or notifications. | F14: Gap – Flow | G14: High | H14: Discovered | I14: 3 | J14: 2 | K14: 5 | L14: Route all transitions through the dedicated approve/activate handlers.
A15: 4 | B15: Gap Analysis | C15: Case Management | D15: Case | E15: Approval workflow integration missing — Case assistance/fund steps are not gated by the approval process. | F15: Gap – Integration | G15: High | H15: Discovered | I15: 5 | J15: 3 | K15: 8 | L15: Depends on Approver settings item.
A16: 5 | B16: Gap Analysis | C16: Fundraising | D16: Payment Reconciliation | E16: Gateway settlement integration missing — reconciliation has no real gateway settlement feed to match against. | F16: Gap – Integration | G16: High | H16: Discovered | I16: 6 | J16: 3 | K16: 9 | L16: Consumes payment-gateway real integration.
A17: 6 | B17: Gap Analysis | C17: Fundraising | D17: Donation (Global) | E17: Receipt auto-generation & email-on-donation not wired for all modes — receipt/comms do not fire consistently after a donation. | F17: Gap – Integration | G17: Medium | H17: Discovered | I17: 4 | J17: 2 | K17: 6 | L17: Confirm receipt number + email across modes.
A18: 7 | B18: Gap Analysis | C18: Communication | D18: Event / Case | E18: Communication service not invoked from Event & Case screens — no send-from-screen (email/SMS/WhatsApp) action. | F18: Gap – Integration | G18: Medium | H18: Discovered | I18: 6 | J18: 3 | K18: 9 | L18: Add contextual send actions.
A19: 8 | B19: Gap Analysis | C19: Communication | D19: Notification | E19: In-app notifications not raised by domain events — key lifecycle events do not produce notifications. | F19: Gap – Integration | G19: Medium | H19: Discovered | I19: 5 | J19: 2 | K19: 7 | L19: Subscribe events to notify service.
A20: 9 | B20: Gap Analysis | C20: Volunteer | D20: Event / P2P / Case | E20: Volunteer assignment not available from Event, P2P and Case screens. | F20: Gap – Integration | G20: Medium | H20: Discovered | I20: 5 | J20: 3 | K20: 8 | L20: Cross-module volunteer picker.
A21: 10 | B21: Gap Analysis | C21: Fundraising | D21: Refund | E21: Refund → gateway reversal + ledger + receipt reversal chain incomplete. | F21: Gap – Flow | G21: Medium | H21: Discovered | I21: 4 | J21: 2 | K21: 6 | L21: Verify downstream reversal effects.
